<?xml version="1.0"?>
<robot name="double_inverted_pendulum">

  <!-- Optional "world" link -->
  <link name="world"/>

  <!-- Cart link -->
  <link name="cart_link">
    <visual>
      <origin xyz="0 0 2.05" rpy="0 0 0"/>
      <geometry>
        <box size="0.5 0.3 0.1"/>
      </geometry>
      <material name="blue">
        <color rgba="0 0 1 1"/>
      </material>
    </visual>
    <collision>
      <origin xyz="0 0 2.05" rpy="0 0 0"/>
      <geometry>
        <box size="0.5 0.3 0.1"/>
      </geometry>
    </collision>
    <inertial>
      <!-- We'll assume a simple diagonal inertia for the cart.
           Adjust or compute realistically as needed. -->
      <origin xyz="0 0 2.05" rpy="0 0 0"/>
      <mass value="1.0"/>
      <inertia ixx="0.1" ixy="0" ixz="0" iyy="0.1" iyz="0" izz="0.1"/>
    </inertial>
  </link>

  <!-- Prismatic joint (x-axis slide) between world and cart -->
  <joint name="cart_slide_joint" type="prismatic">
    <parent link="world"/>
    <child link="cart_link"/>
    <origin xyz="0 0 0" rpy="0 0 0"/>
    <axis xyz="1 0 0"/>
    <limit lower="-5.0" upper="5.0" effort="100.0" velocity="1.0"/>
  </joint>

  <!-- First pendulum -->
  <link name="pendulum_link1">
    <visual>
      <!-- Cylinder along z, pivot at top (z=0), extends to z=-L1 -->
      <origin xyz="0 0 -0.5" rpy="0 0 0"/>
      <geometry>
        <cylinder length="1.0" radius="0.05"/>
      </geometry>
      <material name="green">
        <color rgba="0 1 0 1"/>
      </material>
    </visual>
    <collision>
      <origin xyz="0 0 -0.5" rpy="0 0 0"/>
      <geometry>
        <cylinder length="1.0" radius="0.05"/>
      </geometry>
    </collision>
    <inertial>
      <!-- Inertia specified about the COM (which is at z=-L1/2), so origin is that offset -->
      <origin xyz="0 0 -0.5" rpy="0 0 0"/>
      <mass value="0.5"/>
      <inertia ixx="0.041979166666666665" ixy="0" ixz="0" iyy="0.0006250000000000001" iyz="0" izz="0.041979166666666665"/>
    </inertial>
  </link>

  <!-- Joint for first pendulum (revolute about y-axis) -->
  <joint name="pendulum_joint1" type="revolute">
    <parent link="cart_link"/>
    <child link="pendulum_link1"/>
    <!-- The pivot is at the top face of the cart, i.e. z = zPivot = 0.1 + L1 + L2 -->
    <origin xyz="0 0 2.1" rpy="0 0 0"/>
    <axis xyz="0 1 0"/>
    <limit effort="100.0" velocity="2.0" lower="-3.14159" upper="3.14159"/>
  </joint>

  <!-- Second pendulum -->
  <link name="pendulum_link2">
    <visual>
      <origin xyz="0 0 -0.5" rpy="0 0 0"/>
      <geometry>
        <cylinder length="1.0" radius="0.05"/>
      </geometry>
      <material name="red">
        <color rgba="1 0 0 1"/>
      </material>
    </visual>
    <collision>
      <origin xyz="0 0 -0.5" rpy="0 0 0"/>
      <geometry>
        <cylinder length="1.0" radius="0.05"/>
      </geometry>
    </collision>
    <inertial>
      <origin xyz="0 0 -0.5" rpy="0 0 0"/>
      <mass value="0.5"/>
      <inertia ixx="0.041979166666666665" ixy="0" ixz="0" iyy="0.0006250000000000001" iyz="0" izz="0.041979166666666665"/>
    </inertial>
  </link>

  <!-- Joint for second pendulum (revolute about y-axis) -->
  <joint name="pendulum_joint2" type="revolute">
    <parent link="pendulum_link1"/>
    <child link="pendulum_link2"/>
    <!-- The second pendulum hangs from the bottom of link1, i.e. z=-L1 from pivot1 -->
    <origin xyz="0 0 -1.0" rpy="0 0 0"/>
    <axis xyz="0 1 0"/>
    <limit effort="100.0" velocity="2.0" lower="-3.14159" upper="3.14159"/>
  </joint>

</robot>

