<?xml version="1.0"?>
<robot name="single_inverted_pendulum">

  <!-- Optional "world" link -->
  <link name="world"/>

  <!-- Cart link -->
  <link name="cart_link">
    <visual>
      <origin xyz="0 0 1.05" rpy="0 0 0"/>
      <geometry>
        <box size="0.5 0.3 0.1"/>
      </geometry>
      <material name="blue">
        <color rgba="0 0 1 1"/>
      </material>
    </visual>
    <collision>
      <origin xyz="0 0 1.05" rpy="0 0 0"/>
      <geometry>
        <box size="0.5 0.3 0.1"/>
      </geometry>
    </collision>
    <inertial>
      <origin xyz="0 0 1.05" rpy="0 0 0"/>
      <mass value="1.0"/>
      <inertia ixx="0.1" ixy="0" ixz="0" iyy="0.1" iyz="0" izz="0.1"/>
    </inertial>
  </link>

  <!-- Prismatic joint (x-axis slide) between world and cart -->
  <joint name="cart_slide_joint" type="prismatic">
    <parent link="world"/>
    <child link="cart_link"/>
    <origin xyz="0 0 0" rpy="0 0 0"/>
    <axis xyz="1 0 0"/>
    <limit effort="100.0" velocity="1.0"/>
  </joint>

  <!-- Pendulum link -->
  <link name="pendulum_link">
    <visual>
      <origin xyz="0 0 -0.5" rpy="0 0 0"/>
      <geometry>
        <cylinder length="1.0" radius="0.05"/>
      </geometry>
      <material name="green">
        <color rgba="0 1 0 1"/>
      </material>
    </visual>
    <collision>
      <origin xyz="0 0 -0.5" rpy="0 0 0"/>
      <geometry>
        <cylinder length="1.0" radius="0.05"/>
      </geometry>
    </collision>
    <inertial>
      <origin xyz="0 0 -0.5" rpy="0 0 0"/>
      <mass value="0.5"/>
      <inertia ixx="0.041979166666666665" ixy="0" ixz="0" iyy="0.0006250000000000001" iyz="0" izz="0.041979166666666665"/>
    </inertial>
  </link>

  <!-- Revolute joint for pendulum (y-axis rotation) -->
  <joint name="pendulum_joint" type="revolute">
    <parent link="cart_link"/>
    <child link="pendulum_link"/>
    <origin xyz="0 0 1.1" rpy="0 0 0"/>
    <axis xyz="0 1 0"/>
    <limit effort="100.0" velocity="2.0"/>
  </joint>

</robot>
